            "text": "Unexpected error \"<class 'splunktaucclib.rest_handler.error.RestError'>\" from python handler: \"REST Error [500]: Internal Server Error -- Traceback (most recent call last):\n  File \"/opt/splunk/etc/apps/TA-cofense-triage-add-on-for-splunk/bin/ta_cofense_triage_add_on_for_splunk/aob_py3/splunktaucclib/rest_handler/handler.py\", line 124, in wrapper\n    for name, data, acl in meth(self, *args, **kwargs):\n  File \"/opt/splunk/etc/apps/TA-cofense-triage-add-on-for-splunk/bin/ta_cofense_triage_add_on_for_splunk/aob_py3/splunktaucclib/rest_handler/handler.py\", line 345, in _format_all_response\n    self._encrypt_raw_credentials(cont[\"entry\"])\n  File \"/opt/splunk/etc/apps/TA-cofense-triage-add-on-for-splunk/bin/ta_cofense_triage_add_on_for_splunk/aob_py3/splunktaucclib/rest_handler/handler.py\", line 375, in _encrypt_raw_credentials\n    change_list = rest_credentials.decrypt_all(data)\n  File \"/opt/splunk/etc/apps/TA-cofense-triage-add-on-for-splunk/bin/ta_cofense_triage_add_on_for_splunk/aob_py3/splunktaucclib/rest_handler/credentials.py\", line 293, in decrypt_all\n    all_passwords = credential_manager._get_all_passwords()\n  File \"/opt/splunk/etc/apps/TA-cofense-triage-add-on-for-splunk/bin/ta_cofense_triage_add_on_for_splunk/aob_py3/solnlib/utils.py\", line 153, in wrapper\n    return func(*args, **kwargs)\n  File \"/opt/splunk/etc/apps/TA-cofense-triage-add-on-for-splunk/bin/ta_cofense_triage_add_on_for_splunk/aob_py3/solnlib/credentials.py\", line 341, in _get_all_passwords\n    return self._get_clear_passwords(passwords)\n  File \"/opt/splunk/etc/apps/TA-cofense-triage-add-on-for-splunk/bin/ta_cofense_triage_add_on_for_splunk/aob_py3/solnlib/credentials.py\", line 324, in _get_clear_passwords\n    clear_password += field_clear[index]\nTypeError: can only concatenate str (not \"NoneType\") to str\n\". See splunkd.log/python.log for more details."
