DEBUG [mlspl.util.exec_anaconda_for_model_upload] [exec_anaconda] Error during model file validation: b'Traceback (most recent call last):\n  File "/opt/splunk/etc/apps/Splunk_ML_Toolkit/bin/util/validate_model.py", line 2, in <module>\n    import onnx\n  File "/opt/splunk/etc/apps/Splunk_SA_Scientific_Python_linux_x86_64/bin/linux_x86_64/4_2_0/lib/python3.8/site-packages/onnx/__init__.py", line 78, in <module>\n    from onnx.external_data_helper import (\n  File "/opt/splunk/etc/apps/Splunk_SA_Scientific_Python_linux_x86_64/bin/linux_x86_64/4_2_0/lib/python3.8/site-packages/onnx/external_data_helper.py", line 12, in <module>\n    from onnx.onnx_pb import AttributeProto, GraphProto, ModelProto, TensorProto\n  File "/opt/splunk/etc/apps/Splunk_SA_Scientific_Python_linux_x86_64/bin/linux_x86_64/4_2_0/lib/python3.8/site-packages/onnx/onnx_pb.py", line 4, in <module>\n    from .onnx_ml_pb2 import *  # noqa\n  File "/opt/splunk/etc/apps/Splunk_SA_Scientific_Python_linux_x86_64/bin/linux_x86_64/4_2_0/lib/python3.8/site-packages/onnx/onnx_ml_pb2.py", line 5, in <module>\n    from google.protobuf.internal import builder as _builder\nImportError: cannot import name \'builder\' from \'google.protobuf.internal\' (/opt/splunk/etc/apps/Splunk_SA_Scientific_Python_linux_x86_64/bin/linux_x86_64/4_2_0/lib/python3.8/site-packages/google/protobuf/internal/__init__.py)\n'
